Traceback (most recent call last):
  File "/home/ws/fq0795/git/gnn_uncertainty/evaluate_models.py", line 171, in <module>
    mve.fit(
TypeError: MVE.fit() got an unexpected keyword argument 'force_uncertainty'
